Workbook
Name asd: #REF!
Name beta: #REF!
Name Book_Equity: [1]ABV!$B$28
Name CIQWBInfo: "{ ""CIQVersion"":""9.45.614.5792"" }"
Name Forecast: #REF!
Name Gross_Profit: '[2]Advanced Financial Analysis'!$9:$9
Name IQ_NAMES_REVISION_DATE_: "10/01/2018 15:52:08"
Name Sensitivity: '[2]Advanced Financial Analysis'!$D$49
Name SG_A: '[2]Advanced Financial Analysis'!$11:$11
Name Shares_Out: #REF!
Name Step_1: #REF!
Name Step_2: #REF!
Name Step_3: #REF!
Name Step_4: #REF!
Name Step_5: #REF!
Name Step_6: #REF!
Name Step1: #REF!
Name Step2: #REF!
Name Step3: #REF!
Name Step4: #REF!
Name Step5: #REF!
Name Step6: #REF!
Name Tax_Rate: [1]ABV!$B$29
Name Tax_Rate: [1]ABV!$B$29
Name Tax_Rate: [1]ABV!$B$29
Name Tax_Rate: [1]ABV!$B$29
Name Tax_Rate: #REF!

Sheet Cover
B2: Petrobras Valuation
B9: Prepared by Group 19 : Salma Regaieg - Mustapha Aziz Laroussi
B11: Model Guide | G11: Model Checks
C13: I. Outputs
H14: Valuation Date Check Issue | L14: =-Inputs!F98 -> 0
C15: II. Inputs & Assumptions
H16: Cash Flow Date Check Issue | L16: =Inputs!F99 -> 0
C17: III. DCF Valuation Model
H18: Terminal growth rate > WACC Check Issue | L18: =Inputs!F110 -> 0
C19: IV. Relative Comparables Valuation
H20: Balance Sheet Mismatch | L20: ='3-Statement Analysis'!R60 -> 0
C21: V. Ratios
C23: VI. Assumptions Source
C25: VII. Football Field Chart

Sheet Football Field Chart
B3: Football Field Chart
E36: Low | F36: Middle | G36: High
D37: DCF - Multiple Method | E37: =Outputs!H16 -> 18.049091 | F37: =Outputs!H15 -> 27.352756 | G37: =Outputs!H14 -> 39.983756
D38: DCF - Perpetuity Method | E38: =Outputs!I62 -> 20.178266 | F38: =Outputs!I61 -> 40.431239 | G38: =Outputs!I60 -> 68.740942
D39: Comparable Companies | E39: =Comparables!L27 -> 5.8859726 | F39: =G39-E39 -> 6.8815494 | G39: =Comparables!L29 -> 12.767522
D40: ="Average Valuation: "&TEXT(E40,"$0,00") -> Average Valuation: $037 | E40: =AVERAGE(E37:E38,G37:G38) -> 36.738014

Sheet Outputs
B3: Dashboard: Multiple Method
D6: Model Drivers Set To | L6: All figures in USD thousands unless stated
D9: Main Outputs 1 | L9: Selected Inputs
F11: Enterprise | G11: Equity | H11: Equity
F12: Value | G12: Value | H12: Per Share | L12: Terminal Multiple | O12: =+Inputs!$F$108 -> 6.9249444
F13: =Model!$J$395 -> 3.5778236e+08 | L13: WACC | O13: =Inputs!$L$84 -> 0.043493934
D14: =E60 -> Best Case | E14: 1 | F14: 5.2057994e+08 | G14: =F14-$O$14 -> 5.1533994e+08 | H14: =+G14/$O$15 -> 39.983756 | L14: Net Debt | N14: =O60 -> (End of 2024) | O14: =Inputs!$L$94 -> 5240000
D15: =E61 -> Base Case | E15: 2 | F15: 3.5778236e+08 | G15: =F15-$O$14 -> 3.5254236e+08 | H15: =+G15/$O$15 -> 27.352756 | L15: Shares Outstanding | N15: (FD 000) | O15: =Inputs!$F$105 -> 12888733
D16: =E62 -> Worst Case | E16: 3 | F16: 2.3786991e+08 | G16: =F16-$O$14 -> 2.3262991e+08 | H16: =+G16/$O$15 -> 18.049091 | L16: Current Stock Price | N16: (US$/sh) | O16: =Inputs!$F$106 -> 11.6
D20: Enterprise Value 1 | L20: Equity Value per Share
D22: Terminal Multiple | L22: Terminal Multiple
C23: =Model!$J$395 -> 3.5778236e+08 | D23: =E23-0.5 -> 5.9249444 | E23: =F23-0.5 -> 6.4249444 | F23: =+Inputs!$F$108 -> 6.9249444 | G23: =+F23+0.5 -> 7.4249444 | H23: =+G23+0.5 -> 7.9249444 | L23: =D23 -> 5.9249444 | M23: =E23 -> 6.4249444 | N23: =F23 -> 6.9249444 | O23: =G23 -> 7.4249444 | P23: =H23 -> 7.9249444
B24: WACC | C24: =C25-0.01 -> 0.023493934 | D24: 4.1232863e+08 | E24: 4.1232863e+08 | F24: 4.1232863e+08 | G24: 4.1232863e+08 | H24: 4.1232863e+08 | J24: WACC | K24: =C24 -> 0.023493934 | L24: =D37/$O$15 -> 31.584845 | M24: =E37/$O$15 -> 31.584845 | N24: =F37/$O$15 -> 31.584845 | O24: =G37/$O$15 -> 31.584845 | P24: =H37/$O$15 -> 31.584845
C25: =C26-0.01 -> 0.033493934 | D25: 3.8389421e+08 | E25: 3.8389421e+08 | F25: 3.8389421e+08 | G25: 3.8389421e+08 | H25: 3.8389421e+08 | K25: =C25 -> 0.033493934 | L25: =D38/$O$15 -> 29.3787 | M25: =E38/$O$15 -> 29.3787 | N25: =F38/$O$15 -> 29.3787 | O25: =G38/$O$15 -> 29.3787 | P25: =H38/$O$15 -> 29.3787
C26: =Inputs!$L$84 -> 0.043493934 | D26: 3.5778236e+08 | E26: 3.5778236e+08 | F26: 3.5778236e+08 | G26: 3.5778236e+08 | H26: 3.5778236e+08 | K26: =C26 -> 0.043493934 | L26: =D39/$O$15 -> 27.352756 | M26: =E39/$O$15 -> 27.352756 | N26: =F39/$O$15 -> 27.352756 | O26: =G39/$O$15 -> 27.352756 | P26: =H39/$O$15 -> 27.352756
C27: =C26+0.01 -> 0.053493934 | D27: 3.3378036e+08 | E27: 3.3378036e+08 | F27: 3.3378036e+08 | G27: 3.3378036e+08 | H27: 3.3378036e+08 | K27: =C27 -> 0.053493934 | L27: =D40/$O$15 -> 25.490509 | M27: =E40/$O$15 -> 25.490509 | N27: =F40/$O$15 -> 25.490509 | O27: =G40/$O$15 -> 25.490509 | P27: =H40/$O$15 -> 25.490509
C28: =C27+0.01 -> 0.063493934 | D28: 3.1169693e+08 | E28: 3.1169693e+08 | F28: 3.1169693e+08 | G28: 3.1169693e+08 | H28: 3.1169693e+08 | K28: =C28 -> 0.063493934 | L28: =D41/$O$15 -> 23.777119 | M28: =E41/$O$15 -> 23.777119 | N28: =F41/$O$15 -> 23.777119 | O28: =G41/$O$15 -> 23.777119 | P28: =H41/$O$15 -> 23.777119
D33: Equity Value | L33: Premium (Discount) to Stock Price
D35: Terminal Multiple | L35: Terminal Multiple
D36: =D23 -> 5.9249444 | E36: =E23 -> 6.4249444 | F36: =F23 -> 6.9249444 | G36: =G23 -> 7.4249444 | H36: =H23 -> 7.9249444 | L36: =D36 -> 5.9249444 | M36: =E36 -> 6.4249444 | N36: =F36 -> 6.9249444 | O36: =G36 -> 7.4249444 | P36: =H36 -> 7.9249444
B37: WACC | C37: =C24 -> 0.023493934 | D37: =D24-$O$14 -> 4.0708863e+08 | E37: =E24-$O$14 -> 4.0708863e+08 | F37: =F24-$O$14 -> 4.0708863e+08 | G37: =G24-$O$14 -> 4.0708863e+08 | H37: =H24-$O$14 -> 4.0708863e+08 | J37: WACC | K37: =C37 -> 0.023493934 | L37: =L24/$O$16-1 -> 1.7228315 | M37: =M24/$O$16-1 -> 1.7228315 | N37: =N24/$O$16-1 -> 1.7228315 | O37: =O24/$O$16-1 -> 1.7228315 | P37: =P24/$O$16-1 -> 1.7228315
C38: =C25 -> 0.033493934 | D38: =D25-$O$14 -> 3.7865421e+08 | E38: =E25-$O$14 -> 3.7865421e+08 | F38: =F25-$O$14 -> 3.7865421e+08 | G38: =G25-$O$14 -> 3.7865421e+08 | H38: =H25-$O$14 -> 3.7865421e+08 | K38: =C38 -> 0.033493934 | L38: =L25/$O$16-1 -> 1.5326466 | M38: =M25/$O$16-1 -> 1.5326466 | N38: =N25/$O$16-1 -> 1.5326466 | O38: =O25/$O$16-1 -> 1.5326466 | P38: =P25/$O$16-1 -> 1.5326466
C39: =C26 -> 0.043493934 | D39: =D26-$O$14 -> 3.5254236e+08 | E39: =E26-$O$14 -> 3.5254236e+08 | F39: =F26-$O$14 -> 3.5254236e+08 | G39: =G26-$O$14 -> 3.5254236e+08 | H39: =H26-$O$14 -> 3.5254236e+08 | K39: =C39 -> 0.043493934 | L39: =L26/$O$16-1 -> 1.3579962 | M39: =M26/$O$16-1 -> 1.3579962 | N39: =N26/$O$16-1 -> 1.3579962 | O39: =O26/$O$16-1 -> 1.3579962 | P39: =P26/$O$16-1 -> 1.3579962
C40: =C27 -> 0.053493934 | D40: =D27-$O$14 -> 3.2854036e+08 | E40: =E27-$O$14 -> 3.2854036e+08 | F40: =F27-$O$14 -> 3.2854036e+08 | G40: =G27-$O$14 -> 3.2854036e+08 | H40: =H27-$O$14 -> 3.2854036e+08 | K40: =C40 -> 0.053493934 | L40: =L27/$O$16-1 -> 1.1974577 | M40: =M27/$O$16-1 -> 1.1974577 | N40: =N27/$O$16-1 -> 1.1974577 | O40: =O27/$O$16-1 -> 1.1974577 | P40: =P27/$O$16-1 -> 1.1974577
C41: =C28 -> 0.063493934 | D41: =D28-$O$14 -> 3.0645693e+08 | E41: =E28-$O$14 -> 3.0645693e+08 | F41: =F28-$O$14 -> 3.0645693e+08 | G41: =G28-$O$14 -> 3.0645693e+08 | H41: =H28-$O$14 -> 3.0645693e+08 | K41: =C41 -> 0.063493934 | L41: =L28/$O$16-1 -> 1.0497516 | M41: =M28/$O$16-1 -> 1.0497516 | N41: =N28/$O$16-1 -> 1.0497516 | O41: =O28/$O$16-1 -> 1.0497516 | P41: =P28/$O$16-1 -> 1.0497516
P43: These tables require the workbook calculation to be set to automatic to update.
C49: Dashboard: Perpetuity Method
E52: Model Drivers Set To | G52: 2 | M52: All figures in USD thousands unless stated
E55: Main Outputs 1 | M55: Selected Inputs
G57: Enterprise | H57: Equity | I57: Equity
G58: Value | H58: Value | I58: Per Share | M58: Terminal Growth Rate | P58: =Inputs!F107 -> 0.01
G59: =Model!$J$348 -> 5.2634743e+08 | M59: WACC | P59: =Inputs!$L$84 -> 0.043493934
E60: Best Case | F60: 1 | G60: 8.9122363e+08 | H60: =G60-$P$60 -> 8.8598363e+08 | I60: =H60/$P$61 -> 68.740942 | M60: Net Debt | O60: =CONCATENATE("(End of ",Model!$J$5,")") -> (End of 2024) | P60: =Inputs!$L$94 -> 5240000
E61: Base Case | F61: 2 | G61: 5.2634743e+08 | H61: =G61-$P$60 -> 5.2110743e+08 | I61: =H61/$P$61 -> 40.431239 | M61: Shares Outstanding | O61: (FD 000) | P61: =Inputs!F105 -> 12888733
E62: Worst Case | F62: 3 | G62: 2.6531228e+08 | H62: =G62-$P$60 -> 2.6007228e+08 | I62: =H62/$P$61 -> 20.178266 | M62: Current Stock Price | O62: (US$/sh) | P62: =Inputs!$F$106 -> 11.6
E66: Enterprise Value 1 | M66: Equity Value per Share
E68: Terminal Growth Rate | M68: Terminal Growth Rate
D69: =Model!$J$348 -> 5.2634743e+08 | E69: =F69-0.005 -> 0 | F69: =G69-0.005 -> 0.005 | G69: =Inputs!$F$107 -> 0.01 | H69: =G69+0.005 -> 0.015 | I69: =H69+0.005 -> 0.02 | M69: =E69 -> 0 | N69: =F69 -> 0.005 | O69: =G69 -> 0.01 | P69: =H69 -> 0.015 | Q69: =I69 -> 0.02
C70: WACC | D70: =D71-0.01 -> 0.023493934 | E70: 8.1896624e+08 | F70: 1.0095452e+09 | G70: 1.3413573e+09 | H70: 2.0638154e+09 | I70: 4.8540232e+09 | K70: WACC | L70: =D70 -> 0.023493934 | M70: =E83/$P$61 -> 63.134697 | N70: =F83/$P$61 -> 77.921177 | O70: =G83/$P$61 -> 103.66553 | P70: =H83/$P$61 -> 159.71899 | Q70: =I83/$P$61 -> 376.20325
D71: =D72-0.01 -> 0.033493934 | E71: 5.656767e+08 | F71: 6.4587745e+08 | G71: 7.60215e+08 | H71: 9.363769e+08 | I71: 1.2430878e+09 | L71: =D71 -> 0.033493934 | M71: =E84/$P$61 -> 43.482685 | N71: =F84/$P$61 -> 49.705232 | O71: =G84/$P$61 -> 58.576356 | P71: =H84/$P$61 -> 72.244255 | Q71: =I84/$P$61 -> 96.041075
...

Sheet Inputs
B3: Drivers
B5: All figures in USD thousands unless stated | G5: =$F$97 -> 2025 | H5: =G5+1 -> 2026 | I5: =H5+1 -> 2027 | J5: =I5+1 -> 2028 | K5: =J5+1 -> 2029 | L5: =K5+1 -> 2030 | M5: =L5+1 -> 2031 | N5: =M5+1 -> 2032 | O5: Term
B7: Driver Switch | D7: =Outputs!G52 -> 2
B10: Revenue | G10: {=INDEX(G12:G14,$D$7)} -> 0.12 | H10: {=INDEX(H12:H14,$D$7)} -> 0.112 | I10: {=INDEX(I12:I14,$D$7)} -> 0.104 | J10: {=INDEX(J12:J14,$D$7)} -> 0.048 | K10: {=INDEX(K12:K14,$D$7)} -> 0.04 | L10: {=INDEX(L12:L14,$D$7)} -> 0.032 | M10: {=INDEX(M12:M14,$D$7)} -> 0.028 | N10: {=INDEX(N12:N14,$D$7)} -> 0.028 | O10: {=INDEX(O12:O14,$D$7)} -> 0.028
B12: =Outputs!E60 -> Best Case | G12: 0.15 | H12: 0.14 | I12: 0.13 | J12: 0.06 | K12: 0.05 | L12: 0.04 | M12: 0.035 | N12: 0.035 | O12: 0.035
B13: =Outputs!E61 -> Base Case | G13: =G12*0.8 -> 0.12 | H13: =H12*0.8 -> 0.112 | I13: =I12*0.8 -> 0.104 | J13: =J12*0.8 -> 0.048 | K13: =K12*0.8 -> 0.04 | L13: =L12*0.8 -> 0.032 | M13: =M12*0.8 -> 0.028 | N13: =N12*0.8 -> 0.028 | O13: =O12*0.8 -> 0.028
B14: =Outputs!E62 -> Worst Case | G14: =G13*0.7 -> 0.084 | H14: =H13*0.7 -> 0.0784 | I14: =I13*0.7 -> 0.0728 | J14: =J13*0.7 -> 0.0336 | K14: =K13*0.7 -> 0.028 | L14: =L13*0.7 -> 0.0224 | M14: =M13*0.7 -> 0.0196 | N14: =N13*0.7 -> 0.0196 | O14: =O13*0.7 -> 0.0196
B17: COGS% | G17: {=INDEX(G19:G21,$D$7)} -> 0.49 | H17: {=INDEX(H19:H21,$D$7)} -> 0.49 | I17: {=INDEX(I19:I21,$D$7)} -> 0.49 | J17: {=INDEX(J19:J21,$D$7)} -> 0.49 | K17: {=INDEX(K19:K21,$D$7)} -> 0.49 | L17: {=INDEX(L19:L21,$D$7)} -> 0.49 | M17: {=INDEX(M19:M21,$D$7)} -> 0.49 | N17: {=INDEX(N19:N21,$D$7)} -> 0.49 | O17: {=INDEX(O19:O21,$D$7)} -> 0.49
B19: =$B$12 -> Best Case | G19: 0.45 | H19: 0.45 | I19: 0.45 | J19: 0.45 | K19: 0.45 | L19: 0.45 | M19: 0.45 | N19: 0.45 | O19: 0.45
B20: =$B$13 -> Base Case | G20: 0.49 | H20: 0.49 | I20: 0.49 | J20: 0.49 | K20: 0.49 | L20: 0.49 | M20: 0.49 | N20: 0.49 | O20: 0.49
B21: =$B$14 -> Worst Case | G21: 0.5 | H21: 0.502 | I21: 0.505 | J21: 0.508 | K21: 0.51 | L21: 0.51 | M21: 0.51 | N21: 0.51 | O21: 0.51
B24: Capital Expenditure | G24: {=INDEX(G26:G28,$D$7)} -> 18840000 | H24: {=INDEX(H26:H28,$D$7)} -> 19544000 | I24: {=INDEX(I26:I28,$D$7)} -> 19480000 | J24: {=INDEX(J26:J28,$D$7)} -> 20376000 | K24: {=INDEX(K26:K28,$D$7)} -> 19608000 | L24: {=INDEX(L26:L28,$D$7)} -> 19520000 | M24: {=INDEX(M26:M28,$D$7)} -> 19520000 | N24: {=INDEX(N26:N28,$D$7)} -> 19520000 | O24: {=INDEX(O26:O28,$D$7)} -> 19520000
B26: =$B$12 -> Best Case | G26: =G27*0.8 -> 15072000 | H26: =H27*0.8 -> 15635200 | I26: =I27*0.8 -> 15584000 | J26: =J27*0.8 -> 16300800 | K26: =K27*0.8 -> 15686400 | L26: =L27*0.8 -> 15616000 | M26: =M27*0.8 -> 15616000 | N26: =N27*0.8 -> 15616000 | O26: =O27*0.8 -> 15616000
B27: =$B$13 -> Base Case | G27: 18840000 | H27: 19544000 | I27: 19480000 | J27: 20376000 | K27: 19608000 | L27: 19520000 | M27: 19520000 | N27: 19520000 | O27: 19520000
B28: =$B$14 -> Worst Case | G28: =G27*1.1 -> 20724000 | H28: =H27*1.1 -> 21498400 | I28: =I27*1.1 -> 21428000 | J28: =J27*1.1 -> 22413600 | K28: =K27*1.1 -> 21568800 | L28: =L27*1.1 -> 21472000 | M28: =M27*1.1 -> 21472000 | N28: =N27*1.1 -> 21472000 | O28: =O27*1.1 -> 21472000
B31: Inflation Rate | G31: 0.0531 | H31: 0.0432 | I31: 0.0339 | J31: 0.0296 | K31: 0.0296 | L31: 0.0296 | M31: 0.0296 | N31: 0.0296 | O31: 0.0296
B34: Working Capital 1
B35: Accounts Receivable | E35: (Days) | G35: 33.532739 | H35: 34 | I35: 34 | J35: 34 | K35: 34 | L35: 34 | M35: 34 | N35: 34 | O35: 34
B36: Inventory | E36: (Days) | G36: 60 | H36: 60 | I36: 60 | J36: 60 | K36: 60 | L36: 60 | M36: 60 | N36: 60 | O36: 60
B37: Accounts Payable | E37: (Days) | G37: 131.91009 | H37: 86.396187 | I37: 95.511381 | J37: 95.511381 | K37: 95.511381 | L37: 95.511381 | M37: 95.511381 | N37: 95.511381 | O37: 95.511381
L40: We have assumed working capital amounts per day in terminal year are equal to the previous year.
B44: Weighted Average Cost of Capital
B46: All figures in USD thousands unless stated
H48: Average | I48: Debt/ | J48: Debt/ | K48: Levered | L48: Unlevered
B49: Name | D49: Region | F49: Debt | G49: Equity | H49: Tax Rate 1 | I49: Equity | J49: Capital | K49: Beta 2 | L49: Beta 3
F50: Cost of Debt | G50: Cost of Capital
B51: Oil/Gas (Integrated) | D51: Emerging Markets | F51: 0.0738 | G51: 0.10559082 | H51: 0.20852008 | I51: 0.13320997 | J51: 0.11755101 | K51: 0.97960023 | L51: =K51/(1+(1-H51)*I51) -> 0.88616878
B52: Oil/Gas (Production and Exploration) | D52: Emerging Markets | F52: 0.0738 | G52: 0.10323198 | H52: 0.17395945 | I52: 0.27987954 | J52: 0.21867647 | K52: 1.0441717 | L52: =K52/(1+(1-H52)*I52) -> 0.84809831
B53: Oil/Gas Distribution | D53: Emerging Markets | F53: 0.0693 | G53: 0.07587536 | H53: 0.1288961 | I53: 0.56946739 | J53: 0.36284117 | K53: 0.64524477 | L53: =K53/(1+(1-H53)*I53) -> 0.43129453
B54: Oilfield Svcs/Equip. | D54: Emerging Markets | F54: 0.0738 | G54: 0.08869592 | H54: 0.14623911 | I54: 0.48347252 | J54: 0.32590595 | K54: 0.87086793 | L54: =K54/(1+(1-H54)*I54) -> 0.61642587
E57: Average | F57: =AVERAGE(F51:F55) -> 0.072675 | G57: =AVERAGE(G51:G55) -> 0.093348519 | H57: =AVERAGE(H51:H55) -> 0.16440369 | I57: =AVERAGE(I51:I55) -> 0.36650735 | J57: =AVERAGE(J51:J55) -> 0.25624365 | K57: =AVERAGE(K51:K55) -> 0.88497117 | L57: =AVERAGE(L51:L55) -> 0.69549688
E58: Median | F58: =MEDIAN(F51:F55) -> 0.0738 | G58: =MEDIAN(G51:G55) -> 0.095963949 | H58: =MEDIAN(H51:H55) -> 0.16009928 | I58: =MEDIAN(I51:I55) -> 0.38167603 | J58: =MEDIAN(J51:J55) -> 0.27229121 | K58: =MEDIAN(K51:K55) -> 0.92523408 | L58: =MEDIAN(L51:L55) -> 0.73226209
B61: PETR3.SA | H61: PETR4.SA
B63: Market return | F63: {='CAPM Beta '!$AD$12:$AE$12} -> 0.15072761 | G63: 0 | H63: Market return | L63: {='CAPM Beta '!$AD$12:$AE$12} -> 0.15072761 | M63: 0
B64: Risk Free | F64: 0.0404 | H64: Risk Free | L64: 0.0404
B65: Beta | F65: ='CAPM Beta '!$AD$13 -> 0.1300016 | H65: Beta | L65: ='CAPM Beta '!$AE$13 -> 0
B66: Cost of Equity | F66: =F64+F65*(F63-F64) -> 0.054742765 | H66: Cost of Equity | L66: =L64+L65*(L63-L64) -> 0.0404
B70: Capital Structure | H70: Cost of Debt
E72: Current | F72: Target | H72: Pre-Tax Cost of Debt | L72: =F57 -> 0.072675
B73: Total Debt | D73: 52240 | E73: =D73/$D$75 -> 0.40895295 | F73: 0.15 | H73: Tax Rate | L73: 0.34
...

Sheet Model
B3: Revenue Schedule
B5: All figures in USD thousands unless stated | F5: =G5-1 -> 2020 | G5: =H5-1 -> 2021 | H5: =I5-1 -> 2022 | I5: =J5-1 -> 2023 | J5: =K5-1 -> 2024 | K5: =Inputs!$F$97 -> 2025 | L5: =K5+1 -> 2026 | M5: =L5+1 -> 2027 | N5: =M5+1 -> 2028 | O5: =N5+1 -> 2029 | P5: =O5+1 -> 2030 | Q5: =P5+1 -> 2031 | R5: =Q5+1 -> 2032 | S5: Term
B6: {=CONCATENATE("Model Running: ",INDEX(Inputs!$B$12:$B$14,Inputs!$D$7)," Drivers")} -> Model Running: Base Case Drivers
B8: Days in Period | C8: =Inputs!$F$100 -> 365 | F8: 365 | G8: 365 | H8: 365 | I8: 365 | J8: 365 | K8: =$C$8 -> 365 | L8: =$C$8 -> 365 | M8: =$C$8 -> 365 | N8: =$C$8 -> 365 | O8: =$C$8 -> 365 | P8: =$C$8 -> 365 | Q8: =$C$8 -> 365 | R8: =$C$8 -> 365 | S8: =$C$8 -> 365
B9: Plant Capacity | C9: =Inputs!$L$104 -> 0
B15: REVENUE
B17: Revenue Growth | D17: (Units) | G17: =G19/F19-1 -> 0.56410782 | H17: =H19/G19-1 -> 0.48243337 | I17: =I19/H19-1 -> -0.17726594 | J17: =J19/I19-1 -> -0.10734408 | K17: =Inputs!G10 -> 0.12 | L17: =Inputs!H10 -> 0.112 | M17: =Inputs!I10 -> 0.104 | N17: =Inputs!J10 -> 0.048 | O17: =Inputs!K10 -> 0.04 | P17: =Inputs!L10 -> 0.032 | Q17: =Inputs!M10 -> 0.028 | R17: =Inputs!N10 -> 0.028 | S17: =Inputs!O10 -> 0.028
B19: Revenue | F19: 53683000 | G19: 83966000 | H19: 124474000 | I19: 102409000 | J19: 91416000 | K19: =J19*(1+K17) -> 1.0238592e+08 | L19: =K19*(1+L17) -> 1.1385314e+08 | M19: =L19*(1+M17) -> 1.2569387e+08 | N19: =M19*(1+N17) -> 1.3172718e+08 | O19: =N19*(1+O17) -> 1.3699626e+08 | P19: =O19*(1+P17) -> 1.4138014e+08 | Q19: =P19*(1+Q17) -> 1.4533879e+08 | R19: =Q19*(1+R17) -> 1.4940827e+08 | S19: =R19*(1+S17) -> 1.535917e+08
B25: Cost Schedule
B27: All figures in USD thousands unless stated | F27: =F$5 -> 2020 | G27: =G$5 -> 2021 | H27: =H$5 -> 2022 | I27: =I$5 -> 2023 | J27: =J$5 -> 2024 | K27: =K$5 -> 2025 | L27: =L$5 -> 2026 | M27: =M$5 -> 2027 | ... S27: =S$5 -> Term
B29: COGS % | G29: =G31/G30 -> 0.51406522 | H29: =H31/H30 -> 0.477899 | I29: =I31/I30 -> 0.47295648 | J29: =J31/J30 -> 0.4971121 | K29: =Inputs!G17 -> 0.49 | L29: =Inputs!H17 -> 0.49 | M29: =Inputs!I17 -> 0.49 | N29: =Inputs!J17 -> 0.49 | O29: =Inputs!K17 -> 0.49 | P29: =Inputs!L17 -> 0.49 | Q29: =Inputs!M17 -> 0.49 | R29: =Inputs!N17 -> 0.49 | S29: =Inputs!O17 -> 0.49
B30: Revenue | F30: =F19 -> 53683000 | G30: =G19 -> 83966000 | H30: =H19 -> 124474000 | I30: =I19 -> 102409000 | J30: =J19 -> 91416000 | K30: =K19 -> 1.0238592e+08 | L30: =L19 -> 1.1385314e+08 | M30: =M19 -> 1.2569387e+08 | ... S30: =S19 -> 1.535917e+08
B31: COGS | F31: 29195000 | G31: 43164000 | H31: 59486000 | I31: 48435000 | J31: 45444000 | K31: =K30*K29 -> 50169101 | L31: =L30*L29 -> 55788040 | M31: =M30*M29 -> 61589996 | N31: =N30*N29 -> 64546316 | O31: =O30*O29 -> 67128169 | P31: =P30*P29 -> 69276270 | Q31: =Q30*Q29 -> 71216006 | R31: =R30*R29 -> 73210054 | S31: =S30*S29 -> 75259935
B35: Income Statement
B37: All figures in USD thousands unless stated | F37: =F$5 -> 2020 | G37: =G$5 -> 2021 | H37: =H$5 -> 2022 | I37: =I$5 -> 2023 | J37: =J$5 -> 2024 | K37: =K$5 -> 2025 | L37: =L$5 -> 2026 | M37: =M$5 -> 2027 | ... S37: =S$5 -> Term
B38: =$B$6 -> Model Running: Base Case Drivers
B40: Inflation | F40: 0.0373 | G40: 0.083 | H40: 0.0928 | I40: 0.0459 | J40: 0.0483 | K40: =Inputs!G31 -> 0.0531 | L40: =Inputs!H31 -> 0.0432 | M40: =Inputs!I31 -> 0.0339 | N40: =Inputs!J31 -> 0.0296 | O40: =Inputs!K31 -> 0.0296 | P40: =Inputs!L31 -> 0.0296 | Q40: =Inputs!M31 -> 0.0296 | R40: =Inputs!N31 -> 0.0296 | S40: =Inputs!O31 -> 0.0296
B42: Interest Expense | C42: =Inputs!$L$105 -> 2520000
B43: Tax Rate | C43: =Inputs!$L$73 -> 0.34
B45: Revenue | F45: =F19 -> 53683000 | G45: =G19 -> 83966000 | H45: =H19 -> 124474000 | I45: =I19 -> 102409000 | J45: =J19 -> 91416000 | K45: =K19 -> 1.0238592e+08 | L45: =L19 -> 1.1385314e+08 | M45: =M19 -> 1.2569387e+08 | ... S45: =S19 -> 1.535917e+08
B46: COGS | F46: =F31 -> 29195000 | G46: =G31 -> 43164000 | H46: =H31 -> 59486000 | I46: =I31 -> 48435000 | J46: =J31 -> 45444000 | K46: =K31 -> 50169101 | L46: =L31 -> 55788040 | M46: =M31 -> 61589996 | ... S46: =S31 -> 75259935
B47: Gross Profit | F47: =F45-F46 -> 24488000 | G47: =G45-G46 -> 40802000 | H47: =H45-H46 -> 64988000 | I47: =I45-I46 -> 53974000 | J47: =J45-J46 -> 45972000 | K47: =K45-K46 -> 52216819 | L47: =L45-L46 -> 58065103 | M47: =M45-M46 -> 64103874 | ... S47: =S45-S46 -> 78331769
B50: SG&A | F50: 4873000 | G50: 6313000 | H50: 6537000 | I50: 8061000 | J50: 9033000 | K50: =J50*(1+K$40) -> 9512652.3 | L50: =K50*(1+L$40) -> 9923598.9 | M50: =L50*(1+M$40) -> 10260009 | N50: =M50*(1+N$40) -> 10563705 | O50: =N50*(1+O$40) -> 10876391 | P50: =O50*(1+P$40) -> 11198332 | Q50: =P50*(1+Q$40) -> 11529803 | R50: =Q50*(1+R$40) -> 11871085 | S50: =R50*(1+S$40) -> 12222469
B51: Other | F51: 245000 | G51: 466000 | H51: 1926000 | I51: 5690000 | J51: 10432000 | K51: =J51*(1+K$40) -> 10985939 | L51: =K51*(1+L$40) -> 11460532 | M51: =L51*(1+M$40) -> 11849044 | N51: =M51*(1+N$40) -> 12199775 | O51: =N51*(1+O$40) -> 12560889 | P51: =O51*(1+P$40) -> 12932691 | Q51: =P51*(1+Q$40) -> 13315499 | R51: =Q51*(1+R$40) -> 13709638 | S51: =R51*(1+S$40) -> 14115443
B52: EBITDA | F52: =F47-SUM(F50:F51) -> 19370000 | G52: =G47-SUM(G50:G51) -> 34023000 | H52: =H47-SUM(H50:H51) -> 56525000 | I52: =I47-SUM(I50:I51) -> 40223000 | J52: =J47-SUM(J50:J51) -> 26507000 | K52: =K47-SUM(K50:K51) -> 31718228 | L52: =L47-SUM(L50:L51) -> 36680972 | M52: =M47-SUM(M50:M51) -> 41994821 | ... S52: =S47-SUM(S50:S51) -> 51993858
B55: Depreciation | F55: 653000 | G55: 696000 | H55: 894000 | I55: 732000 | J55: 816000 | K55: =K149 -> 8988812.5 | L55: =L149 -> 9948412.5 | M55: =M149 -> 10924012 | N55: =N149 -> 11920412 | O55: =O149 -> 12920012 | P55: =P149 -> 13410212 | Q55: =Q149 -> 13410212 | R55: =R149 -> 13410212 | S55: =Inputs!O24 -> 19520000
B56: EBIT | F56: =F52-F55 -> 18717000 | G56: =G52-G55 -> 33327000 | H56: =H52-H55 -> 55631000 | I56: =I52-I55 -> 39491000 | J56: =J52-J55 -> 25691000 | K56: =K52-K55 -> 22729415 | L56: =L52-L55 -> 26732560 | M56: =M52-M55 -> 31070808 | ... S56: =S52-S55 -> 32473858
B58: Interest | F58: 16738000 | G58: 5102000 | H58: 2106000 | I58: 4095000 | J58: 14549000 | K58: =$C$42 -> 2520000 | L58: =$C$42 -> 2520000 | M58: =$C$42 -> 2520000 | N58: =$C$42 -> 2520000 | O58: =$C$42 -> 2520000 | P58: =$C$42 -> 2520000 | Q58: =$C$42 -> 2520000 | R58: =$C$42 -> 2520000 | S58: =$C$42 -> 2520000
B59: EBT | F59: =F56-F58 -> 1979000 | G59: =G56-G58 -> 28225000 | H59: =H56-H58 -> 53525000 | I59: =I56-I58 -> 35396000 | J59: =J56-J58 -> 11142000 | K59: =K56-K58 -> 20209415 | L59: =L56-L58 -> 24212560 | M59: =M56-M58 -> 28550808 | ... S59: =S56-S58 -> 29953858
B61: Current Tax | F61: -1174000 | G61: 8239000 | H61: 16770000 | I61: 10401000 | J61: 3537000 | K61: =K218 -> 4463413.4 | L61: =L218 -> 5991552.2 | M61: =M218 -> 7646625.5 | N61: =N218 -> 8320189.2 | O61: =O218 -> 8873903.2 | P61: =P218 -> 9308797.3 | Q61: =Q218 -> 9678627.3 | R61: =R218 -> 10071550 | S61: =S59*C43 -> 10184312
B62: Deferred Tax | F62: 0 | G62: 0 | H62: 0 | I62: 0 | J62: 0 | K62: =K219 -> 2407787.8 | L62: =L219 -> 2240718.2 | M62: =M219 -> 2060649.4 | N62: =N219 -> 1871979.3 | O62: =O219 -> 1662969.4 | P62: =P219 -> 1585699.4 | Q62: =Q219 -> 1659443.6 | R62: =R219 -> 1722126.2 | S62: =S219 -> 0
B63: Total Tax | F63: =SUM(F61:F62) -> -1174000 | G63: =SUM(G61:G62) -> 8239000 | H63: =SUM(H61:H62) -> 16770000 | I63: =SUM(I61:I62) -> 10401000 | J63: =SUM(J61:J62) -> 3537000 | K63: =SUM(K61:K62) -> 6871201.2 | L63: =SUM(L61:L62) -> 8232270.3 | M63: =SUM(M61:M62) -> 9707274.9 | ... S63: =SUM(S61:S62) -> 10184312
B65: Net Income | F65: =F59-F63 -> 3153000 | G65: =G59-G63 -> 19986000 | H65: =H59-H63 -> 36755000 | I65: =I59-I63 -> 24995000 | J65: =J59-J63 -> 7605000 | K65: =K59-K63 -> 13338214 | L65: =L59-L63 -> 15980289 | M65: =M59-M63 -> 18843534 | ... S65: =S59-S63 -> 19769546
B69: Working Capital Schedule
B71: All figures in USD thousands unless stated | F71: =F$5 -> 2020 | G71: =G$5 -> 2021 | H71: =H$5 -> 2022 | I71: =I$5 -> 2023 | J71: =J$5 -> 2024 | K71: =K$5 -> 2025 | L71: =L$5 -> 2026 | M71: =M$5 -> 2027 | ... R71: =R$5 -> 2032 | S71: Term
B72: =$B$6 -> Model Running: Base Case Drivers
B74: Days in Period | F74: =F$8 -> 365 | G74: =G$8 -> 365 | H74: =H$8 -> 365 | I74: =I$8 -> 365 | J74: =J$8 -> 365 | K74: =K$8 -> 365 | L74: =L$8 -> 365 | M74: =M$8 -> 365 | ... S74: =S$8 -> 365
B75: Revenue | F75: =F45 -> 53683000 | G75: =G45 -> 83966000 | H75: =H45 -> 124474000 | I75: =I45 -> 102409000 | J75: =J45 -> 91416000 | K75: =K45 -> 1.0238592e+08 | L75: =L45 -> 1.1385314e+08 | M75: =M45 -> 1.2569387e+08 | ... S75: =S45 -> 1.535917e+08
B76: COGS | F76: =F46 -> 29195000 | G76: =G46 -> 43164000 | H76: =H46 -> 59486000 | I76: =I46 -> 48435000 | J76: =J46 -> 45444000 | K76: =K46 -> 50169101 | L76: =L46 -> 55788040 | M76: =M46 -> 61589996 | ... S76: =S46 -> 75259935
B79: AMOUNTS PER DAY 1
...

Sheet Comparables
B3: Comparable Company Analysis
C5: Market Data | G5: Financial Data | L5: Valuation
C6: Price | D6: Market Cap | E6: EV | G6: Sales | H6: EBITDA | I6: EBIT | J6: Earnings | L6: EV/Sales | M6: EV/EBITDA | N6: EV/EBIT | O6: P/E | S6: EV/Sales | T6: EV/EBITDA | U6: EV/EBIT | V6: P/E
B7: Company Name | C7: ($/share) | D7: ($MM) | E7: ($MM) | G7: ($MM) | H7: ($MM) | I7: ($MM) | J7: ($MM) | L7: x | M7: x | N7: x | O7: x | S7: x | T7: x | U7: x | V7: x
B8: Petroleo Brasileiro S.A.- Petrobras | C8: 11.61 | D8: 74750 | E8: 136820 | G8: 85530 | H8: 33190 | I8: 24160 | J8: 12990 | L8: =E8/G8 -> 1.5996726 | M8: =E8/H8 -> 4.122326 | N8: =E8/I8 -> 5.6630795 | O8: =D8/J8 -> 5.7544265 | Q8: Petroleo Brasileiro S.A.- Petrobras | S8: 1.5996726 | T8: 4.122326 | U8: 5.6630795 | V8: 5.7544265
B9: SHELL | C9: 74.21 | D9: 218930 | E9: 257930 | G9: 272010 | H9: 48290 | I9: 28930 | J9: 13600 | L9: =E9/G9 -> 0.9482372 | M9: =E9/H9 -> 5.3412715 | N9: =E9/I9 -> 8.9156585 | O9: =D9/J9 -> 16.097794 | Q9: SHELL | S9: 0.9482372 | T9: 5.3412715 | U9: 8.9156585 | V9: 16.097794
B10: Total Energies (TTE) | C10: 59.83 | D10: 143450 | E10: 166280 | G10: 187120 | H10: 37380 | I10: 23940 | J10: 12790 | L10: =E10/G10 -> 0.88862762 | M10: =E10/H10 -> 4.4483681 | N10: =E10/I10 -> 6.9456976 | O10: =D10/J10 -> 11.215794 | Q10: Total Energies (TTE) | S10: 0.88862762 | T10: 4.4483681 | U10: 6.9456976 | V10: 11.215794
B11: Equinor ASA (EQNR) | C11: 25.37 | D11: 74710 | E11: 73110 | G11: 106470 | H11: 37610 | I11: 29650 | J11: 8220 | L11: =E11/G11 -> 0.6866723 | M11: =E11/H11 -> 1.9438979 | N11: =E11/I11 -> 2.4657673 | O11: =D11/J11 -> 9.0888078 | Q11: Equinor ASA (EQNR) | S11: 0.6866723 | T11: 1.9438979 | U11: 2.4657673 | V11: 9.0888078
B12: Candadian Natural Resources (CNQ) | C12: 32.45 | D12: 67720 | E12: 77730 | F12: § | G12: 38000 | H12: 17670 | I12: 11060 | J12: 8320 | L12: =E12/G12 -> 2.0455263 | M12: =E12/H12 -> 4.3989813 | N12: =E12/I12 -> 7.0280289 | O12: =D12/J12 -> 8.1394231 | Q12: Candadian Natural Resources (CNQ) | S12: 2.0455263 | T12: 4.3989813 | U12: 7.0280289 | V12: 8.1394231
B13: ENI (E) | C13: 35.52 | D13: 59620 | E13: 74400 | G13: 87030 | H13: 12710 | I13: 6640 | J13: 2270 | L13: =E13/G13 -> 0.85487763 | M13: =E13/H13 -> 5.8536585 | N13: =E13/I13 -> 11.204819 | O13: =D13/J13 -> 26.264317 | Q13: ENI (E) | S13: 0.85487763 | T13: 5.8536585 | U13: 11.204819 | V13: 26.264317
B14: Suncor Energy | C14: 41.53 | D14: 50210 | E14: 58580 | G14: 49730 | H14: 15400 | I14: 8180 | J14: 5660 | L14: =E14/G14 -> 1.177961 | M14: =E14/H14 -> 3.8038961 | N14: =E14/I14 -> 7.1613692 | O14: =D14/J14 -> 8.8710247 | Q14: Suncor Energy | S14: 1.177961 | T14: 3.8038961 | U14: 7.1613692 | V14: 8.8710247
B15: BP | C15: 34.81 | D15: 87870 | E15: 127540 | G15: 186540 | H15: 26430 | I15: 9110 | J15: 560 | L15: =E15/G15 -> 0.68371395 | M15: =E15/H15 -> 4.825577 | N15: =E15/I15 -> 14 | O15: =D15/J15 -> 156.91071 | Q15: BP | S15: 0.68371395 | T15: 4.825577 | U15: 14 | V15: 156.91071
B17: Average | J17: Average | L17: =AVERAGE(L8:L14) -> 1.1716535 | M17: =AVERAGE(M8:M14) -> 4.2731999 | N17: =AVERAGE(N8:N14) -> 7.0549172 | O17: =AVERAGE(O8:O14) -> 12.204512
B18: Median | J18: Median | L18: =MEDIAN(L8:L14) -> 0.9482372 | M18: =MEDIAN(M8:M14) -> 4.3989813 | N18: =MEDIAN(N8:N14) -> 7.0280289 | O18: =MEDIAN(O8:O14) -> 9.0888078
B19: Minimum | J19: Minimum | L19: =MIN(L8:L14) -> 0.6866723 | M19: =MIN(M8:M14) -> 1.9438979 | N19: =MIN(N8:N14) -> 2.4657673 | O19: =MIN(O8:O14) -> 5.7544265
B20: Max | J20: Max | L20: =MAX(L8:L14) -> 2.0455263 | M20: =MAX(M8:M14) -> 5.8536585 | N20: =MAX(N8:N14) -> 11.204819 | O20: =MAX(O8:O14) -> 26.264317
B22: Net Debt | C22: =Inputs!L94/1000 -> 5240
B23: Number of shares | C23: =Inputs!F105/1000 -> 12888.733
C26: Implied EV (USD m) | G26: Implied Equity Value (USD | L26: Fair Price
B27: EV/Sales | C27: =L18*G8 -> 81102.727 | G27: =C27-$C$22 -> 75862.727 | L27: =G27/$C$23 -> 5.8859726
B28: EV/EBITDA | C28: =M18*H8 -> 146002.19 | G28: =C28-$C$22 -> 140762.19 | L28: =G28/$C$23 -> 10.921337
B29: EV/EBIT | C29: =N18*I8 -> 169797.18 | G29: =C29-$C$22 -> 164557.18 | L29: =G29/$C$23 -> 12.767522
B30: P/E | C30: =O18*J8 -> 118063.61 | G30: =C30-$C$22 -> 112823.61 | L30: =G30/$C$23 -> 8.7536622
B31: Average | L31: =AVERAGE(L27:O30) -> 9.5821234

Sheet CAPM Beta 
W3: Number of weeks | Y3: 52
A4: Date | B4: Adj Close | E4: Close | H4: High | K4: Low | N4: Open | Q4: Volume | W4: % Change Weekly
A5: Ticker | B5: PBR | C5: PBR-A | D5: ^GSPC | E5: PBR | F5: PBR-A | G5: ^GSPC | H5: High_PBR | I5: High_PBR-A | J5: High_^GSPC | K5: Low_PBR | L5: Low_PBR-A | M5: Low_^GSPC | N5: Open_PBR | O5: Open_PBR-A | P5: Open_^GSPC | Q5: Volume_PBR | R5: Volume_PBR-A | S5: Volume_^GSPC | W5: PBR | X5: PBR-A | Y5: S&P 500
A6: 43745 | B6: 4.3184981 | C6: 3.7396441 | D6: 2970.27 | E6: 14.4 | F6: 13.31 | G6: 2970.27 | H6: 14.52 | I6: 13.37 | J6: 2993.28 | K6: 13.95 | L6: 12.81 | M6: 2917.1201 | N6: 14.08 | O6: 12.92 | P6: 2918.55 | Q6: 25292900 | R6: 7548900 | S6: 6815720000 | AD6: PBR
A7: 43752 | B7: 4.3574848 | C7: 3.7593119 | D7: 2986.2 | E7: 14.53 | F7: 13.38 | G7: 2986.2 | H7: 14.77 | I7: 13.52 | J7: 3008.29 | K7: 14.13 | L7: 13.02 | M7: 2962.9399 | N7: 14.2 | O7: 13.11 | P7: 2965.8101 | Q7: 61471400 | R7: 14142900 | S7: 15507120000 | W7: =B7/B6-1 -> 0.0090278337 | X7: =C7/C6-1 -> 0.0052592877 | Y7: =D7/D6-1 -> 0.0053631258 | AB7: Covariance | AD7: =_xlfn.COVARIANCE.S(W7:W319,Y7:Y319) -> 0.00065995749
A8: 43759 | B8: 4.7533464 | C8: 4.1020894 | D8: 3022.55 | E8: 15.85 | F8: 14.6 | G8: 3022.55 | H8: 16.049999 | I8: 14.74 | J8: 3027.3899 | K8: 14.44 | L8: 13.27 | M8: 2991.21 | N8: 14.48 | O8: 13.33 | P8: 2996.48 | Q8: 101649000 | R8: 32232800 | S8: 17288670000 | W8: =B8/B7-1 -> 0.090846358 | X8: =C8/C7-1 -> 0.091180912 | Y8: =D8/D7-1 -> 0.012172694 | AB8: Variance | AD8: =_xlfn.VAR.S(W7:W319) -> 0.0050765336
A9: 43766 | B9: 4.9302859 | C9: 4.2790966 | D9: 3066.9099 | E9: 16.440001 | F9: 15.23 | G9: 3066.9099 | H9: 16.84 | I9: 15.67 | J9: 3066.95 | K9: 15.79 | L9: 14.59 | M9: 3023.1899 | N9: 15.92 | O9: 14.66 | P9: 3032.1201 | Q9: 118030900 | R9: 52604700 | S9: 19004660000 | W9: =B9/B8-1 -> 0.037224193 | X9: =C9/C8-1 -> 0.043150497 | Y9: =D9/D8-1 -> 0.014676304 | AB9: R(PBR) Weekly | AD9: =AVERAGE(W7:W754) -> 0.005741488
A10: 43773 | B10: 4.7443504 | C10: 4.0346575 | D10: 3093.0801 | E10: 15.82 | F10: 14.36 | G10: 3093.0801 | H10: 16.629999 | I10: 15.4 | J10: 3097.77 | K10: 15.53 | L10: 14.13 | M10: 3065.8899 | N10: 16.48 | O10: 15.35 | P10: 3078.96 | Q10: 139901000 | R10: 50447900 | S10: 20794290000 | W10: =B10/B9-1 -> -0.037712924 | X10: =C10/C9-1 -> -0.057124002 | Y10: =D10/D9-1 -> 0.008533073 | AB10: R(PBR) Yearly | AD10: =AD9*Y3 -> 0.29855738
A11: 43780 | B11: 4.6303887 | C11: 4.0065603 | D11: 3120.46 | E11: 15.44 | F11: 14.26 | G11: 3120.46 | H11: 16.049999 | I11: 14.68 | J11: 3120.46 | K11: 15.07 | L11: 13.93 | M11: 3075.8201 | N11: 15.76 | O11: 14.41 | P11: 3080.3301 | Q11: 77522700 | R11: 18401200 | S11: 16692290000 | W11: =B11/B10-1 -> -0.024020506 | X11: =C11/C10-1 -> -0.0069639499 | Y11: =D11/D10-1 -> 0.0088519799 | AB11: Rm weekly | AD11: =AVERAGE(Y7:Y319) -> 0.0028986078
A12: 43787 | B12: 4.6018844 | C12: 4.0208998 | D12: 3110.29 | E12: 15.25 | F12: 14.22 | G12: 3110.29 | H12: 15.56 | I12: 14.48 | J12: 3127.6399 | K12: 14.81 | L12: 13.65 | M12: 3091.4099 | N12: 15.27 | O12: 14.11 | P12: 3117.9099 | Q12: 91900100 | R12: 21447100 | S12: 18074100000 | W12: =B12/B11-1 -> -0.0061559349 | X12: =C12/C11-1 -> 0.0035789919 | Y12: =D12/D11-1 -> -0.0032591099 | AB12: Rm Yearly | AD12: =AD11*Y3 -> 0.15072761
A13: 43794 | B13: 4.4449673 | C13: 3.8795183 | D13: 3140.98 | E13: 14.73 | F13: 13.72 | G13: 3140.98 | H13: 15.28 | I13: 14.21 | J13: 3154.26 | K13: 14.57 | L13: 13.59 | M13: 3117.4399 | N13: 15.23 | O13: 14.2 | P13: 3117.4399 | Q13: 54940700 | R13: 22907000 | S13: 12893650000 | W13: =B13/B12-1 -> -0.034098444 | X13: =C13/C12-1 -> -0.035161658 | Y13: =D13/D12-1 -> 0.0098672281 | AB13: Beta | AD13: =AD7/AD8 -> 0.1300016
A14: 43801 | B14: 4.6803417 | C14: 4.1396599 | D14: 3145.9099 | E14: 15.51 | F14: 14.64 | G14: 3145.9099 | H14: 15.59 | I14: 14.68 | J14: 3150.6001 | K14: 14.55 | L14: 13.62 | M14: 3070.3301 | N14: 14.92 | O14: 13.88 | P14: 3143.8501 | Q14: 73806500 | R14: 40730900 | S14: 17504100000 | W14: =B14/B13-1 -> 0.052953022 | X14: =C14/C13-1 -> 0.067055132 | Y14: =D14/D13-1 -> 0.0015695521 | AB14: Rf | AD14: 0.0404
A15: 43808 | B15: 4.6199903 | C15: 4.1283503 | D15: 3168.8 | E15: 15.31 | F15: 14.6 | G15: 3168.8 | H15: 16.120001 | I15: 15.17 | J15: 3182.6799 | K15: 15.2 | L15: 14.48 | M15: 3126.0901 | N15: 15.28 | O15: 14.48 | P15: 3141.8601 | Q15: 83652800 | R15: 28673000 | S15: 17765280000 | W15: =B15/B14-1 -> -0.012894651 | X15: =C15/C14-1 -> -0.0027320176 | Y15: =D15/D14-1 -> 0.0072761577 | AB15: Expected Return | AD15: =AD14+AD13*(AD12-AD14) -> 0.054742765
A16: 43815 | B16: 4.6954308 | C16: 4.1453152 | D16: 3221.22 | E16: 15.56 | F16: 14.66 | G16: 3221.22 | H16: 15.98 | I16: 15.12 | J16: 3225.6499 | K16: 15.21 | L16: 14.47 | M16: 3183.6299 | N16: 15.21 | O16: 14.57 | P16: 3183.6299 | Q16: 79860600 | R16: 23957900 | S16: 22184930000 | W16: =B16/B15-1 -> 0.016329126 | X16: =C16/C15-1 -> 0.0041093685 | Y16: =D16/D15-1 -> 0.016542515 | AB16: Alpha | AD16: =AD10-AD15 -> 0.24381461
A17: 43822 | B17: 4.8040648 | C17: 4.2357998 | D17: 3240.02 | E17: 15.92 | F17: 14.98 | G17: 3240.02 | H17: 16.129999 | I17: 15.24 | J17: 3247.9299 | K17: 15.65 | L17: 14.73 | M17: 3220.51 | N17: 15.69 | O17: 14.76 | P17: 3226.05 | Q17: 34692000 | R17: 6962400 | S17: 8954750000 | W17: =B17/B16-1 -> 0.023136108 | X17: =C17/C16-1 -> 0.021828164 | Y17: =D17/D16-1 -> 0.0058363133
A18: 43829 | B18: 4.8251872 | C18: 4.3167663 | D18: 3234.8501 | E18: 15.99 | F18: 15.07 | G18: 3234.8501 | H18: 16.290001 | I18: 15.31 | J18: 3258.1399 | K18: 15.75 | L18: 14.8 | M18: 3212.03 | N18: 16.09 | O18: 15.15 | P18: 3240.0901 | Q18: 47135400 | R18: 16546100 | S18: 12861110000 | W18: =B18/B17-1 -> 0.0043967883 | X18: =C18/C17-1 -> 0.019114802 | Y18: =D18/D17-1 -> -0.001595645
A19: 43836 | B19: 4.7195716 | C19: 4.2136455 | D19: 3265.3501 | E19: 15.64 | F19: 14.71 | G19: 3265.3501 | H19: 16.299999 | I19: 15.25 | J19: 3282.99 | K19: 15.6 | L19: 14.68 | M19: 3214.6399 | N19: 15.84 | O19: 15.01 | P19: 3217.55 | Q19: 73897700 | R19: 27154600 | S19: 17721020000 | W19: =B19/B18-1 -> -0.021888398 | X19: =C19/C18-1 -> -0.023888438 | Y19: =D19/D18-1 -> 0.0094285667
A20: 43843 | B20: 4.5747261 | C20: 4.0847435 | D20: 3329.6201 | E20: 15.16 | F20: 14.26 | G20: 3329.6201 | H20: 15.59 | I20: 14.7 | J20: 3329.8799 | K20: 14.73 | L20: 13.94 | M20: 3268.4299 | N20: 15.54 | O20: 14.65 | P20: 3271.1299 | Q20: 86529900 | R20: 23782400 | S20: 18135300000 | W20: =B20/B19-1 -> -0.030690389 | X20: =C20/C19-1 -> -0.030591553 | Y20: =D20/D19-1 -> 0.019682428
A21: 43850 | B21: 4.457037 | C21: 4.0074024 | D21: 3295.47 | E21: 14.77 | F21: 13.99 | G21: 3295.47 | H21: 15.1 | I21: 14.23 | J21: 3337.77 | K21: 14.44 | L21: 13.77 | M21: 3281.53 | N21: 15.1 | O21: 14.21 | P21: 3321.03 | Q21: 69458800 | R21: 33810100 | S21: 15204110000 | W21: =B21/B20-1 -> -0.025725941 | X21: =C21/C20-1 -> -0.018934134 | Y21: =D21/D20-1 -> -0.010256469
A22: 43857 | B22: 4.257874 | C22: 3.7954307 | D22: 3225.52 | E22: 14.11 | F22: 13.25 | G22: 3225.52 | H22: 14.7 | I22: 13.86 | J22: 3293.47 | K22: 14.01 | L22: 13.17 | M22: 3214.6799 | N22: 14.17 | O22: 13.38 | P22: 3247.1599 | Q22: 94569600 | R22: 32642200 | S22: 19282920000 | W22: =B22/B21-1 -> -0.044685059 | X22: =C22/C21-1 -> -0.052895052 | Y22: =D22/D21-1 -> -0.021226093
A23: 43864 | B23: 4.399703 | C23: 3.8383982 | D23: 3327.71 | E23: 14.58 | F23: 13.4 | G23: 3327.71 | H23: 14.98 | I23: 13.79 | J23: 3347.96 | K23: 14.12 | L23: 13.21 | M23: 3235.6599 | N23: 14.24 | O23: 13.32 | P23: 3235.6599 | Q23: 214344700 | R23: 45498700 | S23: 19500010000 | W23: =B23/B22-1 -> 0.033309819 | X23: =C23/C22-1 -> 0.011320865 | Y23: =D23/D22-1 -> 0.031681695 | AB23: Beta PBR | AD23: =SLOPE('CAPM Beta '!Y7:Y317,'CAPM Beta '!W7:W317) -> 0.12976114
A24: 43871 | B24: 4.4178081 | C24: 3.9186041 | D24: 3380.1599 | E24: 14.64 | F24: 13.68 | G24: 3380.1599 | H24: 15.02 | I24: 13.91 | J24: 3385.0901 | K24: 14.23 | L24: 13.21 | M24: 3317.77 | N24: 14.45 | O24: 13.34 | P24: 3318.28 | Q24: 115798600 | R24: 25373100 | S24: 18077170000 | W24: =B24/B23-1 -> 0.0041150573 | X24: =C24/C23-1 -> 0.020895674 | Y24: =D24/D23-1 -> 0.015761575
A25: 43878 | B25: 4.2337327 | C25: 3.7868373 | D25: 3337.75 | E25: 14.03 | F25: 13.22 | G25: 3337.75 | H25: 14.94 | I25: 13.98 | J25: 3393.52 | K25: 13.89 | L25: 13.18 | M25: 3328.45 | N25: 14.32 | O25: 13.37 | P25: 3369.04 | Q25: 81059900 | R25: 23282500 | S25: 15292560000 | W25: =B25/B24-1 -> -0.041666671 | X25: =C25/C24-1 -> -0.033625952 | Y25: =D25/D24-1 -> -0.012546718
A26: 43885 | B26: 3.6513314 | C26: 3.2254009 | D26: 2954.22 | E26: 12.1 | F26: 11.26 | G26: 2954.22 | H26: 13.3 | I26: 12.52 | J26: 3259.8101 | K26: 11.51 | L26: 10.88 | M26: 2855.8401 | N26: 13.14 | O26: 12.5 | P26: 3257.6101 | Q26: 194648700 | R26: 56671200 | S26: 31566850000 | W26: =B26/B25-1 -> -0.13756213 | X26: =C26/C25-1 -> -0.14825998 | Y26: =D26/D25-1 -> -0.11490676
A27: 43892 | B27: 3.1745458 | C27: 2.8329673 | D27: 2972.3701 | E27: 10.52 | F27: 9.8900003 | G27: 2972.3701 | H27: 12.91 | I27: 12.24 | J27: 3136.72 | K27: 10.27 | L27: 9.7200003 | M27: 2901.54 | N27: 12.2 | O27: 11.44 | P27: 2974.28 | Q27: 185800000 | R27: 57378800 | S27: 29965390000 | W27: =B27/B26-1 -> -0.13057858 | X27: =C27/C26-1 -> -0.12166972 | Y27: =D27/D26-1 -> 0.0061438033
A28: 43899 | B28: 1.9855995 | C28: 1.8074844 | D28: 2711.02 | E28: 6.5799999 | F28: 6.3099999 | G28: 2711.02 | H28: 8.5699997 | I28: 7.8899999 | J28: 2882.5901 | K28: 4.8299999 | L28: 4.5500002 | M28: 2478.8601 | N28: 7.5500002 | O28: 7.1799998 | P28: 2863.8899 | Q28: 352597000 | R28: 105456400 | S28: 40664410000 | W28: =B28/B27-1 -> -0.37452484 | X28: =C28/C27-1 -> -0.3619819 | Y28: =D28/D27-1 -> -0.087926499 | AB28: SUMMARY OUTPUT PBR
A29: 43906 | B29: 1.4635496 | C29: 1.3634907 | D29: 2304.9199 | E29: 4.8499999 | F29: 4.7600002 | G29: 2304.9199 | H29: 5.96 | I29: 5.6700001 | J29: 2562.98 | K29: 4.0100002 | L29: 4.1599998 | M29: 2280.52 | N29: 5.4000001 | O29: 4.9200001 | P29: 2508.5901 | Q29: 230755900 | R29: 83601700 | S29: 41985050000 | W29: =B29/B28-1 -> -0.26291803 | X29: =C29/C28-1 -> -0.24564178 | Y29: =D29/D28-1 -> -0.14979605
A30: 43913 | B30: 1.5661492 | C30: 1.5009857 | D30: 2541.47 | E30: 5.1900001 | F30: 5.2399998 | G30: 2541.47 | H30: 6.1599998 | I30: 6.0799999 | J30: 2637.01 | K30: 4.4499998 | L30: 4.3800001 | M30: 2191.8601 | N30: 4.6100001 | O30: 4.4699998 | P30: 2290.71 | Q30: 202178800 | R30: 44837300 | S30: 37243200000 | W30: =B30/B29-1 -> 0.070103275 | X30: =C30/C29-1 -> 0.10084047 | Y30: =D30/D29-1 -> 0.10262832 | AB30: Regression Statistics
A31: 43920 | B31: 1.7381542 | C31: 1.6585315 | D31: 2488.6499 | E31: 5.7600002 | F31: 5.79 | G31: 2488.6499 | H31: 6.4200001 | I31: 6.3899999 | J31: 2641.3899 | K31: 4.8800001 | L31: 4.9499998 | M31: 2447.49 | N31: 5.1500001 | O31: 5.1799998 | P31: 2558.98 | Q31: 188500000 | R31: 52880500 | S31: 30852490000 | W31: =B31/B30-1 -> 0.10982666 | X31: =C31/C30-1 -> 0.10496156 | Y31: =D31/D30-1 -> -0.020783275 | AB31: Multiple R | AC31: 0.34287407
A32: 43927 | B32: 2.0278463 | C32: 1.8790966 | D32: 2789.8201 | E32: 6.7199998 | F32: 6.5599999 | G32: 2789.8201 | H32: 7.46 | I32: 7.3699999 | J32: 2818.5701 | K32: 5.8600001 | L32: 5.73 | M32: 2574.5701 | N32: 5.9499998 | O32: 5.9400001 | P32: 2578.28 | Q32: 165291000 | R32: 46832500 | S32: 27229510000 | W32: =B32/B31-1 -> 0.16666655 | X32: =C32/C31-1 -> 0.13298817 | Y32: =D32/D31-1 -> 0.12101749 | AB32: R Square | AC32: 0.11756263
A33: 43934 | B33: 1.9463705 | C33: 1.7616531 | D33: 2874.5601 | E33: 6.4499998 | F33: 6.1500001 | G33: 2874.5601 | H33: 6.8800001 | I33: 6.6999998 | J33: 2879.22 | K33: 6.0500002 | L33: 5.9099998 | M33: 2721.1699 | N33: 6.6799998 | O33: 6.52 | P33: 2782.46 | Q33: 136073600 | R33: 41113200 | S33: 27176880000 | W33: =B33/B32-1 -> -0.040178515 | X33: =C33/C32-1 -> -0.062500012 | Y33: =D33/D32-1 -> 0.030374715 | AB33: Adjusted R Square | AC33: 0.11472521
A34: 43941 | B34: 1.7079779 | C34: 1.6127005 | D34: 2836.74 | E34: 5.6599998 | F34: 5.6300001 | G34: 2836.74 | H34: 6.5999999 | I34: 6.4200001 | J34: 2868.98 | K34: 5.5100002 | L34: 5.4400001 | M34: 2727.1001 | N34: 6.0300002 | O34: 5.8699999 | P34: 2845.6201 | Q34: 202952000 | R34: 94496400 | S34: 26590900000 | W34: =B34/B33-1 -> -0.12248058 | X34: =C34/C33-1 -> -0.084552746 | Y34: =D34/D33-1 -> -0.01315682 | AB34: Standard Error | AC34: 0.067038252
A35: 43948 | B35: 1.9825824 | C35: 1.8103489 | D35: 2830.71 | E35: 6.5700002 | F35: 6.3200002 | G35: 2830.71 | H35: 7.2199998 | I35: 6.9000001 | J35: 2954.8601 | K35: 5.6900001 | L35: 5.6300001 | M35: 2821.6101 | N35: 5.8299999 | O35: 5.7600002 | P35: 2854.6499 | Q35: 156461900 | R35: 36301000 | S35: 28845520000 | W35: =B35/B34-1 -> 0.16077758 | X35: =C35/C34-1 -> 0.12255742 | Y35: =D35/D34-1 -> -0.0021256898 | AB35: Observations | AC35: 313
A36: 43955 | B36: 2.0700929 | C36: 1.8647742 | D36: 2929.8 | E36: 6.8600001 | F36: 6.5100002 | G36: 2929.8 | H36: 6.9699998 | I36: 6.71 | J36: 2932.1599 | K36: 6.23 | L36: 5.9400001 | M36: 2797.8501 | N36: 6.4499998 | O36: 6.2600002 | P36: 2815.01 | Q36: 132187400 | R36: 44792900 | S36: 24823610000 | W36: =B36/B35-1 -> 0.044139635 | X36: =C36/C35-1 -> 0.030063464 | Y36: =D36/D35-1 -> 0.035005384
A37: 43962 | B37: 1.8407536 | C37: 1.6929057 | D37: 2863.7 | E37: 6.0999999 | F37: 5.9099998 | G37: 2863.7 | H37: 6.8699999 | I37: 6.5599999 | J37: 2945.8201 | K37: 5.7399998 | L37: 5.6199999 | M37: 2766.6399 | N37: 6.7399998 | O37: 6.4200001 | P37: 2915.46 | Q37: 157511700 | R37: 43260600 | S37: 27249840000 | W37: =B37/B36-1 -> -0.11078699 | X37: =C37/C36-1 -> -0.092165883 | Y37: =D37/D36-1 -> -0.0225613 | AB37: ANOVA
A38: 43969 | B38: 2.1304457 | C38: 1.936386 | D38: 2955.45 | E38: 7.0599999 | F38: 6.7600002 | G38: 2955.45 | H38: 7.3400002 | I38: 7.0999999 | J38: 2980.29 | K38: 6.5500002 | L38: 6.29 | M38: 2913.8601 | N38: 6.6500001 | O38: 6.4200001 | P38: 2913.8601 | Q38: 140378100 | R38: 40989900 | S38: 25310860000 | W38: =B38/B37-1 -> 0.15737694 | X38: =C38/C37-1 -> 0.14382392 | Y38: =D38/D37-1 -> 0.032038971 | AC38: df | AD38: SS | AE38: MS | AF38: F | AG38: Significance F
A39: 43976 | B39: 2.3024509 | C39: 2.1598151 | D39: 3044.3101 | E39: 7.6300001 | F39: 7.54 | G39: 3044.3101 | H39: 7.8899999 | I39: 7.5799999 | J39: 3068.6699 | K39: 7.3899999 | L39: 7.1300001 | M39: 2969.75 | N39: 7.7600002 | O39: 7.4499998 | P39: 3004.0801 | Q39: 105351800 | R39: 56544700 | S39: 24991070000 | W39: =B39/B38-1 -> 0.080736709 | X39: =C39/C38-1 -> 0.11538458 | Y39: =D39/D38-1 -> 0.030066524 | AB39: Regression | AC39: 1 | AD39: 0.18620491 | AE39: 0.18620491 | AF39: 41.432942 | AG39: 4.6138567e-10
A40: 43983 | B40: 2.8033762 | C40: 2.5608418 | D40: 3193.9299 | E40: 9.29 | F40: 8.9399996 | G40: 3193.9299 | H40: 9.4099998 | I40: 9.0699997 | J40: 3211.72 | K40: 7.6300001 | L40: 7.4899998 | M40: 3031.54 | N40: 7.6999998 | O40: 7.54 | P40: 3038.78 | Q40: 154807100 | R40: 77335000 | S40: 30977470000 | W40: =B40/B39-1 -> 0.21756177 | X40: =C40/C39-1 -> 0.18567642 | Y40: =D40/D39-1 -> 0.049147383 | AB40: Residual | AC40: 311 | AD40: 1.3976736 | AE40: 0.0044941272
A41: 43990 | B41: 2.558949 | C41: 2.3517354 | D41: 3041.3101 | E41: 8.4799995 | F41: 8.21 | G41: 3041.3101 | H41: 9.7200003 | I41: 9.3500004 | J41: 3233.1299 | K41: 8.0299997 | L41: 7.8400002 | M41: 2984.47 | N41: 9.3400002 | O41: 9.0299997 | P41: 3199.9199 | Q41: 171198600 | R41: 59298100 | S41: 34390750000 | W41: =B41/B40-1 -> -0.087190297 | X41: =C41/C40-1 -> -0.081655355 | Y41: =D41/D40-1 -> -0.047784352 | AB41: Total | AC41: 312 | AD41: 1.5838785
A42: 43997 | B42: 2.5378263 | C42: 2.2829878 | D42: 3097.74 | E42: 8.4099998 | F42: 7.9699998 | G42: 3097.74 | H42: 8.9499998 | I42: 8.6099997 | J42: 3155.53 | K42: 7.54 | L42: 7.5500002 | M42: 2965.6599 | N42: 7.8099999 | O42: 7.6100001 | P42: 2993.76 | Q42: 113463300 | R42: 42640600 | S42: 28959080000 | W42: =B42/B41-1 -> -0.0082544412 | X42: =C42/C41-1 -> -0.029232677 | Y42: =D42/D41-1 -> 0.018554482
...

Sheet Assumption Origin
A3: Capex
A4: Industry Name | B4: Number of Firms | C4: Capital Expenditures (US $ millions) | D4: Depreciation & Amort ((US $ millions) | E4: Cap Ex/Deprecn | F4: Acquisitions (US $ millions) | G4: Net R&D (US $ millions) | H4: Net Cap Ex/Sales | I4: Net Cap Ex/ EBIT (1-t) | J4: Sales/ Invested Capital (LTM)
A5: Oil/Gas (Integrated) | B5: 16 | C5: 134000.87 | D5: 94754.431 | E5: 1.4141911 | F5: 119.56 | G5: 458.4336 | H5: 0.024878342 | I5: 0.24370902 | J5: 1.6614566
A6: Oil/Gas (Production and Exploration) | B6: 107 | C6: 36628.439 | D6: 20018.191 | E6: 1.8297577 | F6: 581.095 | G6: 67.6406 | H6: 0.12803494 | I6: 0.49118159 | J6: 0.69009198
A7: Oil/Gas Distribution | B7: 114 | C7: 12408.627 | D7: 5200.327 | E7: 2.3861244 | F7: 744.807 | G7: -1.2308 | H7: 0.05249038 | I7: 0.71075431 | J7: 1.3616032
A8: Oilfield Svcs/Equip. | B8: 231 | C8: 48844.391 | D8: 18395.986 | E8: 2.6551657 | F8: 1464.586 | G8: 145.798 | H8: 0.04090491 | I8: 1.1203162 | J8: 1.8902384
C9: =AVERAGE(C5:C8) -> 57970.582
A11: Inflation | C11: 2025 | D11: 2026 | E11: 2027 | F11: 2028 | G11: 2029 | H11: 2030 | I11: 2031 | J11: 2032
A12: Link: https://www.statista.com/statistics/270812/inflation-rate-in-brazil/ | C12: 0.0531 | D12: 0.0432 | E12: 0.0339 | F12: 0.0296 | G12: 0.0296 | H12: 0.0296 | I12: 0.0296
A14: Industry Name | B14: Number of Firms | C14: ROE | D14: Retention Ratio | E14: Fundamental Growth
A15: Oil/Gas (Integrated) | B15: 16 | C15: 0.18539314 | D15: 0.023678222 | E15: 0.0043897798
A16: Oil/Gas (Production and Exploration) | B16: 107 | C16: 0.2041186 | D16: 0.61615781 | E16: 0.12576927 | F16: =AVERAGE(E16:E18) -> 0.066252138
A17: Oil/Gas Distribution | B17: 114 | C17: 0.12946556 | D17: 0.38307555 | E17: 0.04959509
A18: Oilfield Svcs/Equip. | B18: 231 | C18: 0.077377615 | D18: 0.30231039 | E18: 0.023392057
A21: Industry Name | B21: Number of firms | C21: % of Money Losing firms (Trailing) | D21: Current PE | E21: Trailing PE | F21: Forward PE | G21: Aggregate Mkt Cap/ Net Income (all firms) | H21: Aggregate Mkt Cap/ Trailing Net Income (only money making firms) | I21: Expected growth - next 5 years | J21: PEG Ratio
A22: Oil/Gas (Integrated) | B22: 16 | C22: 0.0625 | D22: 13.269849 | E22: 13.873799 | F22: 9.2634496 | G22: 13.497112 | H22: 14.524554 | I22: -0.035151667 | J22: NA
A23: Oil/Gas (Production and Exploration) | B23: 107 | C23: 0.34579439 | D23: 18.308903 | E23: 16.583415 | F23: 10.332455 | G23: 8.8396194 | H23: 7.1936159 | I23: 0.13173077 | J23: 0.54608471
A24: Oil/Gas Distribution | B24: 114 | C24: 0.28070175 | D24: 28.785715 | E24: 29.032067 | F24: 13.238545 | G24: 11.81363 | H24: 10.495837 | I24: 0.142225 | J24: 0.73797414 | O24: =111/4 -> 27.75
A25: Oilfield Svcs/Equip. | B25: 231 | C25: 0.31168831 | D25: 38.445908 | E25: 47.680259 | F25: 13.705427 | G25: 13.974806 | H25: 16.024041 | I25: 0.10008261 | J25: 1.6010815
A28: Industry Name | B28: Number of firms | C28: EV/EBITDAR&D | D28: EV/EBITDA | E28: EV/EBIT | F28: EV/EBIT (1-t) | G28: EV/EBITDAR&D | H28: EV/EBITDA | I28: EV/EBIT | J28: EV/EBIT (1-t)
A29: Oil/Gas (Integrated) | B29: 16 | C29: 6.3716102 | D29: 6.4910779 | E29: 8.4487573 | F29: 14.758196 | G29: 6.031739 | H29: 6.1386827 | I29: 8.449675 | J29: 14.759799
A30: Oil/Gas (Production and Exploration) | B30: 107 | C30: 3.870222 | D30: 3.9174712 | E30: 5.7944438 | F30: 7.9471817 | G30: 4.3156102 | H30: 4.3726588 | I30: 5.9732072 | J30: 8.1923588 | K30: =AVERAGE(C29:C32) -> 6.8919083
A31: Oil/Gas Distribution | B31: 114 | C31: 8.2195711 | D31: 8.3354787 | E31: 11.831129 | F31: 13.574772 | G31: 8.6656214 | H31: 8.7929993 | I31: 11.972943 | J31: 13.737486
A32: Oilfield Svcs/Equip. | B32: 231 | C32: 9.1062301 | D32: 9.4204189 | E32: 15.119007 | F32: 20.07069 | G32: 8.1545809 | H32: 8.3954367 | I32: 15.73958 | J32: 20.894508
G33: =AVERAGE(G29:G32) -> 6.7918879 | H33: =AVERAGE(H29:H32) -> 6.9249444
A36: Industry Name | B36: Number of Firms | C36: Beta | D36: Cost of Equity | E36: E/(D+E) | F36: Std Dev in Stock | G36: Cost of Debt | H36: Tax Rate | I36: After-tax Cost of Debt | J36: D/(D+E) | K36: Cost of Capital | L36: Cost of Capital (Local Currency) | M36: D/E
A37: Oil/Gas (Integrated) | B37: 16 | C37: 0.97960023 | D37: 0.11231486 | E37: 0.88244899 | F37: 0.32648391 | G37: 0.0738 | H37: 0.20852008 | I37: 0.05511384 | J37: 0.11755101 | K37: 0.10559082 | L37: 0.16999417 | M37: =J37/E37 -> 0.13320997
A38: Oil/Gas (Production and Exploration) | B38: 107 | C38: 1.0441717 | D38: 0.11669926 | E38: 0.78132353 | F38: 0.3641026 | G38: 0.0738 | H38: 0.17395945 | I38: 0.05511384 | J38: 0.21867647 | K38: 0.10323198 | L38: 0.16749792 | M38: =J38/E38 -> 0.27987954
A39: Oil/Gas Distribution | B39: 114 | C39: 0.64524477 | D39: 0.08961212 | E39: 0.63715883 | F39: 0.27750198 | G39: 0.0693 | H39: 0.1288961 | I39: 0.05175324 | J39: 0.36284117 | K39: 0.07587536 | L39: 0.13854771 | M39: =J39/E39 -> 0.56946739
A40: Oilfield Svcs/Equip. | B40: 231 | C40: 0.87086793 | D40: 0.10493193 | E40: 0.67409405 | F40: 0.37800031 | G40: 0.0738 | H40: 0.14623911 | I40: 0.05511384 | J40: 0.32590595 | K40: 0.08869592 | L40: 0.1521151 | M40: =J40/E40 -> 0.48347252
C41: =AVERAGE(C38:C40) -> 0.85342814
A43: Industry Name | B43: Number of firms | C43: Total Dividends (US $ millions) | D43: Special Dividends as % of Total Dividends | E43: Dividend Payout | F43: Dividend Yield | G43: Market Cap (US $ millions) | H43: ROE | I43: Institutional Holdings | J43: Std Dev in Stock Prices
A44: Oil/Gas (Integrated) | B44: 4 | C44: 4026.8 | D44: 0 | E44: 0.32620777 | F44: 0.038545664 | G44: 104468.3 | H44: 0.17768048 | I44: 0.47545 | J44: 0.38036214
A45: Oil/Gas (Production and Exploration) | B45: 210 | C45: 9512.4579 | D45: 0.080331709 | E45: 0.66305618 | F45: 0.047705954 | G45: 199397.71 | H45: 0.092683546 | I45: 0.13408204 | J45: 0.58775055
A46: Oil/Gas Distribution | B46: 9 | C46: 10358.08 | D46: -0.00011102444 | E46: 0.98813918 | F46: 0.058441073 | G46: 177239.73 | H46: 0.13169869 | I46: 0.3728 | J46: 0.28841974
A47: Oilfield Svcs/Equip. | B47: 30 | C47: 967.76 | D47: 0.010312474 | E47: 0.66419043 | F47: 0.045046873 | G47: 21483.4 | H47: 0.12450906 | I47: 0.30156913 | J47: 0.46485369

Sheet Sheet2
B3: 0.11 | C3: 0.27 | D3: 0.09 | E3: 2.04 | F3: 6.45 | G3: 2.98 | H3: 2.35
C4: =C3/B3-1 -> 1.4545455 | D4: =D3/C3-1 -> -0.66666667 | E4: =E3/D3-1 -> 21.666667 | F4: =F3/E3-1 -> 2.1617647 | G4: =G3/F3-1 -> -0.5379845 | H4: =H3/G3-1 -> -0.2114094

Sheet Ratios
B6: Income Statement Analysis
B7: Years | C7: 2020 | D7: =C7+1 -> 2021 | E7: =D7+1 -> 2022 | F7: =E7+1 -> 2023 | G7: =F7+1 -> 2024
B8: Sales&Revenues | C8: ='Income Statement PBR'!B3 -> 53683000000 | D8: ='Income Statement PBR'!C3 -> 83966000000 | E8: ='Income Statement PBR'!D3 -> 124474000000 | F8: ='Income Statement PBR'!E3 -> 102409000000 | G8: ='Income Statement PBR'!F3 -> 91416000000
B9: Variation | D9: =(D8-C8)/C8 -> 0.56410782 | E9: =(E8-D8)/D8 -> 0.48243337 | F9: =(F8-E8)/E8 -> -0.17726594 | G9: =(G8-F8)/F8 -> -0.10734408
B10: COGS | C10: ='Income Statement PBR'!B6 -> -29195000000 | D10: ='Income Statement PBR'!C6 -> -43164000000 | E10: ='Income Statement PBR'!D6 -> -59486000000 | F10: ='Income Statement PBR'!E6 -> -48435000000 | G10: ='Income Statement PBR'!F6 -> -45444000000
B11: Gross Profit | C11: =C8+C10 -> 24488000000 | D11: =D8+D10 -> 40802000000 | E11: =E8+E10 -> 64988000000 | F11: =F8+F10 -> 53974000000 | G11: =G8+G10 -> 45972000000
B12: Gross Margin (%) | C12: =C11/C8 -> 0.45615931 | D12: =D11/D8 -> 0.48593478 | E12: =E11/E8 -> 0.522101 | F12: =F11/F8 -> 0.52704352 | G12: =G11/G8 -> 0.5028879
B13: EBITDA | C13: =C16-C15 -> 17165000000 | D13: =D16-D15 -> 34023000000 | E13: =E16-E15 -> 56525000000 | F13: =F16-F15 -> 40223000000 | G13: =G16-G15 -> 26507000000
B14: EBITDA margin | C14: =C13/C8 -> 0.31974741 | D14: =D13/D8 -> 0.40519972 | E14: =E13/E8 -> 0.4541109 | F14: =F13/F8 -> 0.39276821 | G14: =G13/G8 -> 0.28996018
B15: Depr&Amort | C15: ='Income Statement PBR'!B24 -> -653000000 | D15: ='Income Statement PBR'!C24 -> -696000000 | E15: ='Income Statement PBR'!D24 -> -894000000 | F15: ='Income Statement PBR'!E24 -> -732000000 | G15: ='Income Statement PBR'!F24 -> -816000000
B16: EBIT | C16: ='Income Statement PBR'!B33 -> 16512000000 | D16: ='Income Statement PBR'!C33 -> 33327000000 | E16: ='Income Statement PBR'!D33 -> 55631000000 | F16: ='Income Statement PBR'!E33 -> 39491000000 | G16: ='Income Statement PBR'!F33 -> 25691000000
B17: EBIT margin | C17: =C16/C8 -> 0.30758341 | D17: =D16/D8 -> 0.39691065 | E17: =E16/E8 -> 0.44692868 | F17: =F16/F8 -> 0.3856204 | G17: =G16/G8 -> 0.28103395
B18: Intrest Charges | C18: ='Income Statement PBR'!B36 -> -5692000000 | D18: ='Income Statement PBR'!C36 -> -4977000000 | E18: ='Income Statement PBR'!D36 -> -2638000000 | F18: ='Income Statement PBR'!E36 -> -3620000000 | G18: ='Income Statement PBR'!F36 -> -3841000000
B19: Taxes | C19: ='Income Statement PBR'!B61 -> 1174000000 | D19: ='Income Statement PBR'!C61 -> -8239000000 | E19: ='Income Statement PBR'!D61 -> -16770000000 | F19: ='Income Statement PBR'!E61 -> -10401000000 | G19: ='Income Statement PBR'!F61 -> -3537000000
B20: Net Income | C20: ='Income Statement PBR'!B66 -> 1141000000 | D20: ='Income Statement PBR'!C66 -> 19875000000 | E20: ='Income Statement PBR'!D66 -> 36623000000 | F20: ='Income Statement PBR'!E66 -> 24884000000 | G20: ='Income Statement PBR'!F66 -> 7528000000
B21: Variation | D21: =(D20-C20)/C20 -> 16.418931 | E21: =(E20-D20)/D20 -> 0.84266667 | F21: =(F20-E20)/E20 -> -0.32053628 | G21: =(G20-F20)/F20 -> -0.69747629
B22: Earnings per share | C22: =C20/C25 -> 0.087471818 | D22: =D20/D25 -> 1.5236655 | E22: =E20/E25 -> 2.8076077 | F22: =F20/F25 -> 1.923009 | G22: =G20/G25 -> 0.58407604
B23: Number of Common share | C23: 7442231382 | D23: 7442231382 | E23: 7442231382 | F23: 7442231382 | G23: 7442231382
B24: Number of Preferred share | C24: 5601969879 | D24: 5601969879 | E24: 5601969879 | F24: 5497905879 | G24: 5446501379
B25: Total number of Shares | C25: =C23+C24 -> 13044201261 | D25: =D23+D24 -> 13044201261 | E25: =E23+E24 -> 13044201261 | F25: =F23+F24 -> 12940137261 | G25: =G23+G24 -> 12888732761
B26: Dividends per share | C26: ='Income Statement PBR'!B88 -> 0.04 | D26: ='Income Statement PBR'!C88 -> 1.05 | E26: ='Income Statement PBR'!D88 -> 3.31 | F26: ='Income Statement PBR'!E88 -> 1.46 | G26: ='Income Statement PBR'!F88 -> 1.21
B27: Div Yield PBR | C27: =C26/C66 -> 0.0035618878 | D27: =D26/D66 -> 0.095628415 | E27: =E26/E66 -> 0.31079812 | F27: =F26/F66 -> 0.091421415 | G27: =G26/G66 -> 0.094090202
B28: Div Yield PBR.A | C28: =C26/C68 -> 0.0003115648 | D28: =D26/D68 -> 0.14570572 | E28: =E26/E68 -> 0.8725992 | F28: =F26/F68 -> 0.1758042 | G28: =G26/G68 -> 0.054955833
B30: Balance Sheet
B31: Total Assets | C31: ='Balance Sheet PBR'!B2 -> 190010000000 | D31: ='Balance Sheet PBR'!C2 -> 174348000000 | E31: ='Balance Sheet PBR'!D2 -> 187191000000 | F31: ='Balance Sheet PBR'!E2 -> 217067000000 | G31: ='Balance Sheet PBR'!F2 -> 181645000000
B32: Cash & cash equivalents | C32: ='Balance Sheet PBR'!B5 -> 11711000000 | D32: ='Balance Sheet PBR'!C5 -> 10467000000 | E32: ='Balance Sheet PBR'!D5 -> 7996000000 | F32: ='Balance Sheet PBR'!E5 -> 12727000000 | G32: ='Balance Sheet PBR'!F5 -> 3271000000
B33: Accounts Receivable | C33: ='Balance Sheet PBR'!B13 -> 7326000000 | D33: ='Balance Sheet PBR'!C13 -> 7714000000 | E33: ='Balance Sheet PBR'!D13 -> 6317000000 | F33: ='Balance Sheet PBR'!E13 -> 7313000000 | G33: ='Balance Sheet PBR'!F13 -> 5532000000
B34: Inventory | C34: ='Balance Sheet PBR'!B10 -> 5677000000 | D34: ='Balance Sheet PBR'!C10 -> 7255000000 | E34: ='Balance Sheet PBR'!D10 -> 8779000000 | F34: ='Balance Sheet PBR'!E10 -> 7681000000 | G34: ='Balance Sheet PBR'!F10 -> 6710000000
B35: Current Assets | C35: ='Balance Sheet PBR'!B3 -> 27388000000 | D35: ='Balance Sheet PBR'!C3 -> 30149000000 | E35: ='Balance Sheet PBR'!D3 -> 31250000000 | F35: ='Balance Sheet PBR'!E3 -> 32445000000 | G35: ='Balance Sheet PBR'!F3 -> 21836000000
B36: Accounts Payable | C36: ='Balance Sheet PBR'!B76 -> 6859000000 | D36: ='Balance Sheet PBR'!C76 -> 5483000000 | E36: ='Balance Sheet PBR'!D76 -> 5464000000 | F36: ='Balance Sheet PBR'!E76 -> 4813000000 | G36: ='Balance Sheet PBR'!F76 -> 6082000000
B37: Current liabilities | C37: ='Balance Sheet PBR'!B73 -> 26225000000 | D37: ='Balance Sheet PBR'!C73 -> 24176000000 | E37: ='Balance Sheet PBR'!D73 -> 31380000000 | F37: ='Balance Sheet PBR'!E73 -> 33860000000 | G37: ='Balance Sheet PBR'!F73 -> 31460000000
B38: Debt | C38: ='Balance Sheet PBR'!B80 -> 9884000000 | D38: ='Balance Sheet PBR'!C80 -> 9073000000 | E38: ='Balance Sheet PBR'!D80 -> 9133000000 | F38: ='Balance Sheet PBR'!E80 -> 11522000000 | G38: ='Balance Sheet PBR'!F80 -> 11108000000
B39: Book Equity | C39: ='Balance Sheet PBR'!B114 -> 59876000000 | D39: ='Balance Sheet PBR'!C114 -> 69812000000 | E39: ='Balance Sheet PBR'!D114 -> 69836000000 | F39: ='Balance Sheet PBR'!E114 -> 78975000000 | G39: ='Balance Sheet PBR'!F114 -> 59350000000
B40: Price/Book | C40: =(C25*C66)/C39 -> 2.4464958 | D40: =(D25*D66)/D39 -> 2.0515861 | E40: =(E25*E66)/E39 -> 1.9892426 | F40: =(F25*F66)/F39 -> 2.6167014 | G40: =(G25*G66)/G39 -> 2.7927397
B41: BV per share | C41: =C39/C25 -> 4.5902389 | D41: =D39/D25 -> 5.3519567 | E41: =E39/E25 -> 5.3537966 | F41: =F39/F25 -> 6.1031037 | G41: =G39/G25 -> 4.6047972
B43: Liquidity Ratios | H43: Average
B44: Current Ratio | C44: =C35/C37 -> 1.044347 | D44: =D35/D37 -> 1.2470632 | E44: =E35/E37 -> 0.99585723 | F44: =F35/F37 -> 0.95821028 | G44: =G35/G37 -> 0.69408773 | H44: =AVERAGE(C44:G44) -> 0.98791309
B45: Quick Ration | C45: =(C35-C34)/C37 -> 0.82787417 | D45: =(D35-D34)/D37 -> 0.9469722 | E45: =(E35-E34)/E37 -> 0.71609305 | F45: =(F35-F34)/F37 -> 0.73136444 | G45: =(G35-G34)/G37 -> 0.48080102 | H45: =AVERAGE(C45:G45) -> 0.74062098
B46: Cash Ratio | C46: =C32/C37 -> 0.44655863 | D46: =D32/D37 -> 0.43295003 | E46: =E32/E37 -> 0.25481198 | F46: =F32/F37 -> 0.37587123 | G46: =G32/G37 -> 0.1039733 | H46: =AVERAGE(C46:G46) -> 0.32283304
B48: Efficiency Ratio | H48: Average
...

Sheet 3-Statement Analysis
D1: Historical Results | I1: Forecast Period
D2: 2020 | E2: =+D2+1 -> 2021 | F2: =+E2+1 -> 2022 | G2: =+F2+1 -> 2023 | H2: =+G2+1 -> 2024 | I2: =+H2+1 -> 2025 | J2: =+I2+1 -> 2026 | K2: =+J2+1 -> 2027 | L2: =+K2+1 -> 2028 | ... P2: =+O2+1 -> 2032
A3: Balance Sheet Check | D3: =IFERROR(IF(ABS(D60)>1,"ERROR","OK"),"OK") -> OK | E3: =IFERROR(IF(ABS(E60)>1,"ERROR","OK"),"OK") -> OK | F3: =IFERROR(IF(ABS(F60)>1,"ERROR","OK"),"OK") -> OK | G3: =IFERROR(IF(ABS(G60)>1,"ERROR","OK"),"OK") -> OK | H3: =IFERROR(IF(ABS(H60)>1,"ERROR","OK"),"OK") -> OK | I3: =IFERROR(IF(ABS(I60)>1,"ERROR","OK"),"OK") -> OK | J3: =IFERROR(IF(ABS(J60)>1,"ERROR","OK"),"OK") -> OK | K3: =IFERROR(IF(ABS(K60)>1,"ERROR","OK"),"OK") -> OK | ... P3: =IFERROR(IF(ABS(P60)>1,"ERROR","OK"),"OK") -> OK
A4: All-in ($000's)
A5: Assumptions
A7: Key Assumptions
A8: Revenue Growth (% Change) | E8: =E26/D26-1 -> 0.56410782 | F8: =F26/E26-1 -> 0.48243337 | G8: =G26/F26-1 -> -0.17726594 | H8: =H26/G26-1 -> -0.10734408 | I8: 0.1162 | J8: 0.1162 | K8: 0.0618 | L8: 0.0618 | M8: 0.0618 | N8: 0.0618 | O8: 0.0618 | P8: 0.0618
